{"is_success": "Fail", "type": "weather_now", "std_day": "20221111", "params": {"ServiceKey": "lWLaCFJasDo6vpnFordk0ZVBBDk0eu0yL+KUjEF56K+w78w4lsKg7BJANNWeWbL2mzl72Q4LfFyIygL5qCGGkA==", "pageNo": "1", "numOfRows": "1000", "dataType": "JSON", "base_date": "20221111", "base_time": "0800", "nx": "60", "ny": "127"}, "err_msg": "HTTPConnectionPool(host='localhost', port=9870): Max retries exceeded with url: /webhdfs/v1/final_data/weather_now/weather_now_20221111.json?user.name=big&overwrite=True&op=CREATE (Caused by NewConnectionError('<urllib3.connection.HTTPConnection object at 0x7f28c41293d0>: Failed to establish a new connection: [Errno 111] Connection refused'))"}
{"is_success": "Fail", "type": "weather_now", "std_day": "20221111", "params": {"ServiceKey": "lWLaCFJasDo6vpnFordk0ZVBBDk0eu0yL+KUjEF56K+w78w4lsKg7BJANNWeWbL2mzl72Q4LfFyIygL5qCGGkA==", "pageNo": "1", "numOfRows": "1000", "dataType": "JSON", "base_date": "20221111", "base_time": "0800", "nx": "60", "ny": "127"}, "err_msg": "HTTPConnectionPool(host='localhost', port=9870): Max retries exceeded with url: /webhdfs/v1/final_data/weather_now/weather_now_20221111.json?user.name=big&overwrite=True&op=CREATE (Caused by NewConnectionError('<urllib3.connection.HTTPConnection object at 0x7f01880ce5e0>: Failed to establish a new connection: [Errno 111] Connection refused'))"}
{"is_success": "Fail", "type": "weather_now", "std_day": "20221111", "params": {"ServiceKey": "lWLaCFJasDo6vpnFordk0ZVBBDk0eu0yL+KUjEF56K+w78w4lsKg7BJANNWeWbL2mzl72Q4LfFyIygL5qCGGkA==", "pageNo": "1", "numOfRows": "1000", "dataType": "JSON", "base_date": "20221111", "base_time": "0800", "nx": "60", "ny": "127"}, "err_msg": "HTTPConnectionPool(host='localhost', port=9870): Max retries exceeded with url: /webhdfs/v1/final_data/weather_now/weather_now_20221111.json?user.name=big&overwrite=True&op=CREATE (Caused by NewConnectionError('<urllib3.connection.HTTPConnection object at 0x7f3982c6e250>: Failed to establish a new connection: [Errno 111] Connection refused'))"}
{"is_success": "Fail", "type": "weather_now", "std_day": "20221111", "params": {"ServiceKey": "lWLaCFJasDo6vpnFordk0ZVBBDk0eu0yL+KUjEF56K+w78w4lsKg7BJANNWeWbL2mzl72Q4LfFyIygL5qCGGkA==", "pageNo": "1", "numOfRows": "1000", "dataType": "JSON", "base_date": "20221111", "base_time": "0800", "nx": "60", "ny": "127"}, "err_msg": "HTTPConnectionPool(host='localhost', port=9870): Max retries exceeded with url: /webhdfs/v1/final_data/weather_now/weather_now_20221111.json?user.name=big&overwrite=True&op=CREATE (Caused by NewConnectionError('<urllib3.connection.HTTPConnection object at 0x7f9fcc07f2e0>: Failed to establish a new connection: [Errno 111] Connection refused'))"}
{"is_success": "Fail", "type": "weather_now", "std_day": "20221111", "params": {"ServiceKey": "lWLaCFJasDo6vpnFordk0ZVBBDk0eu0yL+KUjEF56K+w78w4lsKg7BJANNWeWbL2mzl72Q4LfFyIygL5qCGGkA==", "pageNo": "1", "numOfRows": "1000", "dataType": "JSON", "base_date": "20221111", "base_time": "0800", "nx": "60", "ny": "127"}, "err_msg": "HTTPConnectionPool(host='localhost', port=9870): Max retries exceeded with url: /webhdfs/v1/final_data/weather_now/weather_now_20221111.json?user.name=big&overwrite=True&op=CREATE (Caused by NewConnectionError('<urllib3.connection.HTTPConnection object at 0x7fcc580d9550>: Failed to establish a new connection: [Errno 111] Connection refused'))"}
{"is_success": "Fail", "type": "weather_now", "std_day": "20221111", "params": {"ServiceKey": "lWLaCFJasDo6vpnFordk0ZVBBDk0eu0yL+KUjEF56K+w78w4lsKg7BJANNWeWbL2mzl72Q4LfFyIygL5qCGGkA==", "pageNo": "1", "numOfRows": "1000", "dataType": "JSON", "base_date": "20221111", "base_time": "0800", "nx": "60", "ny": "127"}, "err_msg": "HTTPConnectionPool(host='apis.data.go.kr', port=80): Max retries exceeded with url: /1360000/VilageFcstInfoService_2.0/getVilageFcst?ServiceKey=lWLaCFJasDo6vpnFordk0ZVBBDk0eu0yL%2BKUjEF56K%2Bw78w4lsKg7BJANNWeWbL2mzl72Q4LfFyIygL5qCGGkA%3D%3D&pageNo=1&numOfRows=1000&dataType=JSON&base_date=20221111&base_time=0800&nx=60&ny=127 (Caused by NewConnectionError('<urllib3.connection.HTTPConnection object at 0x7f4bd24b1100>: Failed to establish a new connection: [Errno 111] Connection refused'))"}
{"is_success": "Fail", "type": "weather_now", "std_day": "20221111", "params": {"ServiceKey": "lWLaCFJasDo6vpnFordk0ZVBBDk0eu0yL+KUjEF56K+w78w4lsKg7BJANNWeWbL2mzl72Q4LfFyIygL5qCGGkA==", "pageNo": "1", "numOfRows": "1000", "dataType": "JSON", "base_date": "20221111", "base_time": "0800", "nx": "60", "ny": "127"}, "err_msg": "HTTPConnectionPool(host='localhost', port=9870): Max retries exceeded with url: /webhdfs/v1/final_data/weather_now/weather_now_20221111.json?user.name=big&overwrite=True&op=CREATE (Caused by NewConnectionError('<urllib3.connection.HTTPConnection object at 0x7f85b4127190>: Failed to establish a new connection: [Errno 111] Connection refused'))"}
{"is_success": "Fail", "type": "weather_now", "std_day": "20221111", "params": {"ServiceKey": "lWLaCFJasDo6vpnFordk0ZVBBDk0eu0yL+KUjEF56K+w78w4lsKg7BJANNWeWbL2mzl72Q4LfFyIygL5qCGGkA==", "pageNo": "1", "numOfRows": "1000", "dataType": "JSON", "base_date": "20221111", "base_time": "0800", "nx": "60", "ny": "127"}, "err_msg": "HTTPConnectionPool(host='localhost', port=9870): Max retries exceeded with url: /webhdfs/v1/final_data/weather_now/weather_now_20221111.json?user.name=big&overwrite=True&op=CREATE (Caused by NewConnectionError('<urllib3.connection.HTTPConnection object at 0x7fe1d40d3040>: Failed to establish a new connection: [Errno 111] Connection refused'))"}
{"is_success": "Fail", "type": "weather_now", "std_day": "20221111", "params": {"ServiceKey": "lWLaCFJasDo6vpnFordk0ZVBBDk0eu0yL+KUjEF56K+w78w4lsKg7BJANNWeWbL2mzl72Q4LfFyIygL5qCGGkA==", "pageNo": "1", "numOfRows": "1000", "dataType": "JSON", "base_date": "20221111", "base_time": "0800", "nx": "60", "ny": "127"}, "err_msg": "HTTPConnectionPool(host='apis.data.go.kr', port=80): Max retries exceeded with url: /1360000/VilageFcstInfoService_2.0/getVilageFcst?ServiceKey=lWLaCFJasDo6vpnFordk0ZVBBDk0eu0yL%2BKUjEF56K%2Bw78w4lsKg7BJANNWeWbL2mzl72Q4LfFyIygL5qCGGkA%3D%3D&pageNo=1&numOfRows=1000&dataType=JSON&base_date=20221111&base_time=0800&nx=60&ny=127 (Caused by NewConnectionError('<urllib3.connection.HTTPConnection object at 0x7fa4580542e0>: Failed to establish a new connection: [Errno 111] Connection refused'))"}
